2023-02-21 21:20:12,646 ERROR: Exception on /edit_profile [POST] [in /home/runner/microblog/venv/lib/python3.10/site-packages/flask/app.py:1741]
Traceback (most recent call last):
  File "/home/runner/microblog/venv/lib/python3.10/site-packages/sqlalchemy/engine/base.py", line 1964, in _exec_single_context
    self.dialect.do_execute(
  File "/home/runner/microblog/venv/lib/python3.10/site-packages/sqlalchemy/engine/default.py", line 747, in do_execute
    cursor.execute(statement, parameters)
sqlite3.IntegrityError: UNIQUE constraint failed: user.username

The above exception was the direct cause of the following exception:

Traceback (most recent call last):
  File "/home/runner/microblog/venv/lib/python3.10/site-packages/flask/app.py", line 2525, in wsgi_app
    response = self.full_dispatch_request()
  File "/home/runner/microblog/venv/lib/python3.10/site-packages/flask/app.py", line 1822, in full_dispatch_request
    rv = self.handle_user_exception(e)
  File "/home/runner/microblog/venv/lib/python3.10/site-packages/flask/app.py", line 1820, in full_dispatch_request
    rv = self.dispatch_request()
  File "/home/runner/microblog/venv/lib/python3.10/site-packages/flask/app.py", line 1796, in dispatch_request
    return self.ensure_sync(self.view_functions[rule.endpoint])(**view_args)
  File "/home/runner/microblog/venv/lib/python3.10/site-packages/flask_login/utils.py", line 290, in decorated_view
    return current_app.ensure_sync(func)(*args, **kwargs)
  File "/home/runner/microblog/app/routes.py", line 101, in edit_profile
    db.session.commit()
  File "/home/runner/microblog/venv/lib/python3.10/site-packages/sqlalchemy/orm/scoping.py", line 538, in commit
    return self._proxied.commit()
  File "/home/runner/microblog/venv/lib/python3.10/site-packages/sqlalchemy/orm/session.py", line 1903, in commit
    trans.commit(_to_root=True)
  File "<string>", line 2, in commit
  File "/home/runner/microblog/venv/lib/python3.10/site-packages/sqlalchemy/orm/state_changes.py", line 137, in _go
    ret_value = fn(self, *arg, **kw)
  File "/home/runner/microblog/venv/lib/python3.10/site-packages/sqlalchemy/orm/session.py", line 1218, in commit
    self._prepare_impl()
  File "<string>", line 2, in _prepare_impl
  File "/home/runner/microblog/venv/lib/python3.10/site-packages/sqlalchemy/orm/state_changes.py", line 137, in _go
    ret_value = fn(self, *arg, **kw)
  File "/home/runner/microblog/venv/lib/python3.10/site-packages/sqlalchemy/orm/session.py", line 1193, in _prepare_impl
    self.session.flush()
  File "/home/runner/microblog/venv/lib/python3.10/site-packages/sqlalchemy/orm/session.py", line 4153, in flush
    self._flush(objects)
  File "/home/runner/microblog/venv/lib/python3.10/site-packages/sqlalchemy/orm/session.py", line 4289, in _flush
    with util.safe_reraise():
  File "/home/runner/microblog/venv/lib/python3.10/site-packages/sqlalchemy/util/langhelpers.py", line 147, in __exit__
    raise exc_value.with_traceback(exc_tb)
  File "/home/runner/microblog/venv/lib/python3.10/site-packages/sqlalchemy/orm/session.py", line 4250, in _flush
    flush_context.execute()
  File "/home/runner/microblog/venv/lib/python3.10/site-packages/sqlalchemy/orm/unitofwork.py", line 467, in execute
    rec.execute(self)
  File "/home/runner/microblog/venv/lib/python3.10/site-packages/sqlalchemy/orm/unitofwork.py", line 644, in execute
    util.preloaded.orm_persistence.save_obj(
  File "/home/runner/microblog/venv/lib/python3.10/site-packages/sqlalchemy/orm/persistence.py", line 85, in save_obj
    _emit_update_statements(
  File "/home/runner/microblog/venv/lib/python3.10/site-packages/sqlalchemy/orm/persistence.py", line 894, in _emit_update_statements
    c = connection.execute(
  File "/home/runner/microblog/venv/lib/python3.10/site-packages/sqlalchemy/engine/base.py", line 1414, in execute
    return meth(
  File "/home/runner/microblog/venv/lib/python3.10/site-packages/sqlalchemy/sql/elements.py", line 485, in _execute_on_connection
    return connection._execute_clauseelement(
  File "/home/runner/microblog/venv/lib/python3.10/site-packages/sqlalchemy/engine/base.py", line 1638, in _execute_clauseelement
    ret = self._execute_context(
  File "/home/runner/microblog/venv/lib/python3.10/site-packages/sqlalchemy/engine/base.py", line 1842, in _execute_context
    return self._exec_single_context(
  File "/home/runner/microblog/venv/lib/python3.10/site-packages/sqlalchemy/engine/base.py", line 1983, in _exec_single_context
    self._handle_dbapi_exception(
  File "/home/runner/microblog/venv/lib/python3.10/site-packages/sqlalchemy/engine/base.py", line 2325, in _handle_dbapi_exception
    raise sqlalchemy_exception.with_traceback(exc_info[2]) from e
  File "/home/runner/microblog/venv/lib/python3.10/site-packages/sqlalchemy/engine/base.py", line 1964, in _exec_single_context
    self.dialect.do_execute(
  File "/home/runner/microblog/venv/lib/python3.10/site-packages/sqlalchemy/engine/default.py", line 747, in do_execute
    cursor.execute(statement, parameters)
sqlalchemy.exc.IntegrityError: (sqlite3.IntegrityError) UNIQUE constraint failed: user.username
[SQL: UPDATE user SET username=?, about_me=? WHERE user.id = ?]
[parameters: ('susan', "Wow! Python's Flask is a minimalist web framework. Love it.", 2)]
(Background on this error at: https://sqlalche.me/e/20/gkpj)
